Workbook

Sheet Pivot Table_Thiet bi_1
A1: Eng name | B1: ENG | C1: From | D1: Received date | E1: Count - ENG*
A2: - | B2: Broken display cable | C2: TS | D2: (empty) | E2: 1
B3: Broken mechanical latch, beyond repair | C3: TS | D3: (empty) | E3: 2
B4: Deformed spring, overstretched | C4: TS | D4: (empty) | E4: 1
B5: IC failure | C5: TS | D5: (empty) | E5: 2
B6: Lost, code cancelled | C6: TS | D6: (empty) | E6: 2
B7: Motor and spring failure | C7: HTV | D7: 45233 | E7: 1
B8: Motor failure | C8: 0 | D8: (empty) | E8: 1
C9: HTV | D9: 45233 | E9: 5
D10: (empty) | E10: 1
C11: TS | D11: (empty) | E11: 15
B12: NG: Blown internal circuit in multimeter | C12: TS | D12: (empty) | E12: 1
B13: No power | C13: 0 | D13: (empty) | E13: 1
C14: TS | D14: (empty) | E14: 5
B15: Oxidized | C15: TS | D15: 45996 | E15: 1
D16: (empty) | E16: 5
B17: The plastic is melting | C17: 0 | D17: (empty) | E17: 1
C18: TS | D18: (empty) | E18: 5
B19: Transformer failure | C19: TS | D19: (empty) | E19: 1
B20: (empty) | C20: 0 | D20: (empty)
C21: TS | D21: (empty)
A22: Auto screwdriver machine | B22: Inoperative, missing accessories | C22: TS | D22: (empty) | E22: 1
A23: Automatic tape wrapping machine | B23: Not in use (No purpose), idle for >6 months | C23: TS | D23: (empty) | E23: 1
A24: Barcode Scanner | B24: IC failure | C24: TS | D24: (empty) | E24: 2
A25: Cable Tie Gun | B25: Broken mechanical latch, beyond repair | C25: TS | D25: (empty) | E25: 5
A26: Case | B26: No power, suspected IC failure | C26: Viet Nam | D26: 46101 | E26: 1
A27: Component Lead Cutting Machine | B27: No power | C27: TS | D27: (empty) | E27: 1
B28: Not in use (No purpose), idle for >6 months | C28: TS | D28: (empty) | E28: 2
A29: Digital Oscilloscope | B29: Non-existent, Code overlap, Cancel code | C29: 0 | D29: (empty) | E29: 2
A30: Digital thermometer | B30: Screen damaged beyond repair | C30: TS | D30: (empty) | E30: 1
A31: Digital torque meter | B31: Force sensor and battery failure | C31: TS | D31: (empty) | E31: 1
A32: Electric Solder Pot Tin | B32: Not in use due to no production | C32: TS | D32: (empty) | E32: 2
A33: Electronic Scale | B33: Faulty sensor, inaccurate readings | C33: TS | D33: (empty) | E33: 4
B34: Screen does not turn on | C34: TS | D34: 46030 | E34: 1
D35: (empty) | E35: 2
A36: Feeler gauge | B36: Oxidized | C36: TS | D36: (empty) | E36: 1
A37: Fixture | B37: Discontinued due to new design | C37: TS | D37: 45658 | E37: 1
B38: Lost, not in use | C38: TS | D38: 45658 | E38: 1
B39: Not in use due to no production | C39: TS | D39: (empty) | E39: 16
A40: Force gauge | B40: Warped | C40: TS | D40: (empty) | E40: 2
...

Sheet Thiet bi
A1: TT | B1: Hình | C1: Status | D1: Code | E1: Hiện trạng hỏng | F1: ENG | G1: Ảnh NG | H1: Video NG | I1: Eng name | J1: Vie Name | K1: Manufacturer | L1: Model | M1: Equipment Serial | N1: TS Serial | O1: Use for customer | P1: Use for model | Q1: Equipment No. | R1: FA No. | S1: Calibration Type | T1: Calibration Date | U1: Out of Calibration Date | V1: Status | W1: Tình trạng | X1: Vị trí sử dụng | Y1: Calibration Team | Z1: Mô tả | AA1: Chú thích | AB1: Ý kiến đóng góp | AC1: Số tệp báo cáo | AD1: Tên tệp báo cáo | AE1: Link báo cáo | AF1: slf | AG1: Received date | AH1: From
A2: 1 | C2: NG | D2: PIE00001 | E2: Hỏng motor, lò xo | F2: Motor and spring failure | I2: - | J2: - | K2: - | L2: - | M2: - | N2: - | O2: - | P2: - | Q2: - | R2: - | S2: No Need | T2: - | U2: - | V2: . | W2: Scrap | X2: Line 14 | Z2: - | AA2: Súng bắn vít nhỏ | AB2: - | AC2: 0 | AF2: 1 | AG2: =INDEX(Sheet3!Y:Y,MATCH(D2,Sheet3!A:A,0)) -> 45233 | AH2: =INDEX(Sheet3!X:X,MATCH(D2,Sheet3!A:A,0)) -> HTV
A3: 2 | C3: NG | D3: PIE00002 | E3: Hỏng motor, lò xo | F3: Motor and spring failure | I3: Screw driver | J3: Súng bắn vít | K3: Shuang Ai | L3: POL-SDGS-0115 | M3: - | N3: - | O3: Common | P3: - | Q3: - | R3: - | S3: No Need | T3: - | U3: - | V3: Không cần hiệu chuẩn | W3: Scrap | X3: REPAIR | Z3: 24VDC, 0,1 ~ 1 Nm | AA3: Súng bắn vít nhỏ | AB3: - | AC3: 0 | AF3: 1 | AG3: =INDEX(Sheet3!Y:Y,MATCH(D3,Sheet3!A:A,0)) -> 45233 | AH3: =INDEX(Sheet3!X:X,MATCH(D3,Sheet3!A:A,0)) -> HTV
A4: 3 | C4: NG | D4: PIE00003 | E4: Hỏng motor, lò xo | F4: Motor and spring failure | I4: Screw driver | J4: Súng bắn vít | K4: Shuang Ai | L4: POL-SDGS-0115 | M4: - | N4: - | O4: Common | P4: - | Q4: 50662 | R4: - | S4: No Need | T4: - | U4: - | V4: Không cần hiệu chuẩn | W4: Scrap | X4: JIG | Z4: 24VDC, 0,1 ~ 1 Nm | AA4: Súng bắn vít nhỏ | AB4: - | AC4: 0 | AF4: 1 | AH4: =INDEX(Sheet3!X:X,MATCH(D4,Sheet3!A:A,0)) -> TS
A5: 4 | C5: NG | D5: PIE00004 | E5: Hỏng motor, lò xo | F5: Motor and spring failure | I5: Screw driver | J5: Súng bắn vít | K5: Shuang Ai | L5: POL-SDGS-0115 | M5: - | N5: - | O5: Common | P5: - | Q5: - | R5: - | S5: No Need | T5: - | U5: - | V5: Không cần hiệu chuẩn | W5: NG | X5: JIG | Z5: 24VDC, 0,1 ~ 1 Nm | AA5: Súng bắn vít nhỏ | AB5: - | AC5: 0 | AF5: 1 | AG5: =INDEX(Sheet3!Y:Y,MATCH(D5,Sheet3!A:A,0)) -> 45233 | AH5: =INDEX(Sheet3!X:X,MATCH(D5,Sheet3!A:A,0)) -> HTV
A6: 5 | C6: NG | D6: PIE00005 | E6: Hỏng motor | F6: Motor failure | I6: Screw driver | J6: Súng bắn vít | K6: Shuang Ai | L6: POL-SDGS-0530 | M6: - | N6: - | O6: Common | P6: - | Q6: - | R6: - | S6: No Need | T6: - | U6: - | V6: Không cần hiệu chuẩn | W6: NG | X6: JIG | Z6: 24VDC, 0,8 ~ 1,6 Nm | AA6: - | AB6: - | AC6: 0 | AF6: 1 | AG6: =INDEX(Sheet3!Y:Y,MATCH(D6,Sheet3!A:A,0)) -> 45233 | AH6: =INDEX(Sheet3!X:X,MATCH(D6,Sheet3!A:A,0)) -> HTV
A7: 6 | C7: NG | D7: PIE00006 | E7: Hỏng motor | F7: Motor failure | I7: Screw driver | J7: Súng bắn vít | K7: Shuang Ai | L7: POL-SDGS-0530 | M7: - | N7: - | O7: Common | P7: - | Q7: - | R7: - | S7: No Need | T7: - | U7: - | V7: Không cần hiệu chuẩn | W7: Scrap | X7: Line 9 | Z7: 24VDC, 0,8 ~ 1,6 Nm | AA7: Súng xanh | AB7: - | AC7: 0 | AF7: 1 | AG7: =INDEX(Sheet3!Y:Y,MATCH(D7,Sheet3!A:A,0)) -> 45233 | AH7: =INDEX(Sheet3!X:X,MATCH(D7,Sheet3!A:A,0)) -> HTV
A8: 7 | C8: NG | D8: PIE00007 | E8: Hỏng motor | F8: Motor failure | I8: Screw driver | J8: Súng bắn vít | K8: Shuang Ai | L8: POL-SDGS-0530 | M8: - | N8: - | O8: Common | P8: - | Q8: - | R8: - | S8: No Need | T8: - | U8: - | V8: Không cần hiệu chuẩn | W8: NG | X8: Line 14 | Z8: 24VDC, 0,8 ~ 1,6 Nm | AA8: Súng xanh | AB8: - | AC8: 0 | AF8: 1 | AG8: =INDEX(Sheet3!Y:Y,MATCH(D8,Sheet3!A:A,0)) -> 45233 | AH8: =INDEX(Sheet3!X:X,MATCH(D8,Sheet3!A:A,0)) -> HTV
A9: 8 | C9: NG | D9: PIE00008 | E9: Hỏng motor, lò xo | F9: Motor and spring failure | I9: Screw driver | J9: Súng bắn vít | K9: Shuang Ai | L9: POL-SDGS-0115 | M9: - | N9: - | O9: Common | P9: - | Q9: 50661 | R9: - | S9: No Need | T9: - | U9: - | V9: Không cần hiệu chuẩn | W9: Scrap | X9: JIG | Z9: 24VDC, 0,1 ~ 1 Nm | AA9: Súng bắn vít nhỏ | AB9: - | AC9: 0 | AF9: 1 | AH9: =INDEX(Sheet3!X:X,MATCH(D9,Sheet3!A:A,0)) -> HTV
A10: 9 | C10: NG | D10: PIE00008 | E10: Hỏng motor | F10: Motor failure | I10: - | J10: - | K10: - | L10: - | M10: - | N10: - | O10: - | P10: - | Q10: - | R10: - | S10: No Need | T10: - | U10: - | V10: . | W10: Scrap | X10: JIG | Z10: - | AA10: Súng xanh | AB10: - | AC10: 0 | AF10: 1 | AH10: =INDEX(Sheet3!X:X,MATCH(D10,Sheet3!A:A,0)) -> HTV
A11: 10 | C11: NG | D11: PIE00010 | E11: Hỏng motor | F11: Motor failure | I11: Screw driver | J11: Súng bắn vít | K11: Shuang Ai | L11: POL-SDGS-0530 | M11: - | N11: - | O11: Common | P11: - | Q11: - | R11: - | S11: No Need | T11: - | U11: - | V11: Không cần hiệu chuẩn | W11: NG | X11: JIG | Z11: 24VDC, 0,8 ~ 1,6 Nm | AA11: Súng xanh | AB11: - | AC11: 0 | AF11: 1 | AG11: =INDEX(Sheet3!Y:Y,MATCH(D11,Sheet3!A:A,0)) -> 45233 | AH11: =INDEX(Sheet3!X:X,MATCH(D11,Sheet3!A:A,0)) -> HTV
A12: 11 | C12: NG | D12: PIE00011 | E12: Hỏng motor | F12: Motor failure | I12: Screw driver | J12: Súng bắn vít | K12: Shuang Ai | L12: POL-SDGS-0530 | M12: - | N12: - | O12: Common | P12: - | Q12: - | R12: - | S12: No Need | T12: - | U12: - | V12: Không cần hiệu chuẩn | W12: NG | X12: JIG | Z12: 24VDC, 0,8 ~ 1,6 Nm | AA12: Súng xanh | AB12: - | AC12: 0 | AF12: 1 | AG12: =INDEX(Sheet3!Y:Y,MATCH(D12,Sheet3!A:A,0)) -> 45233 | AH12: =INDEX(Sheet3!X:X,MATCH(D12,Sheet3!A:A,0)) -> HTV
A13: 12 | C13: NG | D13: PIE00013 | E13: Hỏng motor | F13: Motor failure | I13: - | J13: - | K13: - | L13: - | M13: - | N13: - | O13: - | P13: - | Q13: - | R13: - | S13: No Need | T13: - | U13: - | V13: . | W13: Scrap | X13: Chưa phân loại | Z13: - | AA13: Súng bắn vít nhỏ | AB13: - | AC13: 0 | AF13: 1 | AG13: =INDEX(Sheet3!Y:Y,MATCH(D13,Sheet3!A:A,0)) -> 45233 | AH13: =INDEX(Sheet3!X:X,MATCH(D13,Sheet3!A:A,0)) -> HTV
A14: 13 | C14: NG | D14: PIE00014 | E14: Hỏng motor, lò xo | F14: Motor and spring failure | I14: Screw driver | J14: Súng bắn vít | K14: Shuang Ai | L14: POL-SDGS-0115 | M14: - | N14: - | O14: Common | P14: - | Q14: - | R14: - | S14: No Need | T14: - | U14: - | V14: Không cần hiệu chuẩn | W14: NG | X14: Line 11 | Z14: 24VDC, 0,1 ~ 1 Nm | AA14: Súng bắn vít nhỏ | AB14: - | AC14: 0 | AF14: 1 | AG14: =INDEX(Sheet3!Y:Y,MATCH(D14,Sheet3!A:A,0)) -> 45233 | AH14: =INDEX(Sheet3!X:X,MATCH(D14,Sheet3!A:A,0)) -> HTV
A15: 14 | C15: NG | D15: PIE00015 | E15: Hỏng motor | F15: Motor failure | I15: - | J15: - | K15: - | L15: - | M15: - | N15: - | O15: - | P15: - | Q15: - | R15: - | S15: No Need | T15: - | U15: - | V15: . | W15: Scrap | X15: JIG | Z15: - | AA15: Súng bắn vít nhỏ | AB15: - | AC15: 0 | AF15: 1 | AG15: =INDEX(Sheet3!Y:Y,MATCH(D15,Sheet3!A:A,0)) -> 45233 | AH15: =INDEX(Sheet3!X:X,MATCH(D15,Sheet3!A:A,0)) -> HTV
A16: 15 | C16: NG | D16: PIE00016 | E16: Hỏng motor | F16: Motor failure | I16: - | J16: - | K16: - | L16: - | M16: - | N16: - | O16: - | P16: - | Q16: - | R16: - | S16: No Need | T16: - | U16: - | V16: . | W16: Scrap | X16: JIG | Z16: - | AA16: Súng bắn vít nhỏ | AB16: - | AC16: 0 | AF16: 1 | AG16: =INDEX(Sheet3!Y:Y,MATCH(D16,Sheet3!A:A,0)) -> 45233 | AH16: =INDEX(Sheet3!X:X,MATCH(D16,Sheet3!A:A,0)) -> HTV
A17: 16 | C17: NG | D17: PIE00017 | E17: Hỏng motor | F17: Motor failure | I17: Screw driver | J17: Súng bắn vít | K17: Shuang Ai | L17: POL-SDGS-0530 | M17: - | N17: - | O17: Common | P17: - | Q17: - | R17: - | S17: No Need | T17: - | U17: - | V17: Không cần hiệu chuẩn | W17: NG | X17: Chưa phân loại | Z17: 24VDC, 0,8 ~ 1,6 Nm | AA17: Súng xanh | AB17: - | AC17: 0 | AF17: 1 | AG17: =INDEX(Sheet3!Y:Y,MATCH(D17,Sheet3!A:A,0)) -> 45233 | AH17: =INDEX(Sheet3!X:X,MATCH(D17,Sheet3!A:A,0)) -> HTV
A18: 17 | C18: NG | D18: PIE00018 | E18: Hỏng motor | F18: Motor failure | I18: Screw driver | J18: Súng bắn vít | K18: Shuang Ai | L18: POL-SDGS-0530 | M18: - | N18: - | O18: Common | P18: - | Q18: - | R18: - | S18: No Need | T18: - | U18: - | V18: Không cần hiệu chuẩn | W18: NG | X18: Line 1 | Z18: 24VDC, 0,8 ~ 1,6 Nm | AA18: Súng xanh | AB18: - | AC18: 0 | AF18: 1 | AG18: =INDEX(Sheet3!Y:Y,MATCH(D18,Sheet3!A:A,0)) -> 45233 | AH18: =INDEX(Sheet3!X:X,MATCH(D18,Sheet3!A:A,0)) -> HTV
A19: 18 | C19: NG | D19: PIE00019 | E19: Không lên nguồn | F19: No power | I19: Soldering Station | J19: Máy hàn | K19: HAKO | L19: SLD 936 | M19: - | N19: - | O19: Common | P19: - | Q19: 50398 | R19: - | S19: No Need | T19: - | U19: - | V19: Không cần hiệu chuẩn | W19: NG | X19: JIG | Z19: 220V, 60W | AA19: - | AB19: - | AC19: 0 | AF19: 1 | AH19: =INDEX(Sheet3!X:X,MATCH(D19,Sheet3!A:A,0)) -> TS
A20: 19 | C20: NG | D20: PIE00026 | E20: Hỏng motor | F20: Motor failure | I20: Screw driver | J20: Súng bắn vít | K20: Shuang Ai | L20: POL-SDGS-0530 | M20: - | N20: - | O20: Common | P20: - | Q20: - | R20: - | S20: No Need | T20: - | U20: - | V20: Không cần hiệu chuẩn | W20: NG | X20: JIG | Z20: 24VDC, 0,8 ~ 1,6 Nm | AA20: Súng xanh | AB20: - | AC20: 0 | AF20: 1 | AG20: =INDEX(Sheet3!Y:Y,MATCH(D20,Sheet3!A:A,0)) -> 45233 | AH20: =INDEX(Sheet3!X:X,MATCH(D20,Sheet3!A:A,0)) -> HTV
A21: 20 | C21: NG | D21: PIE00027 | E21: Hỏng motor | F21: Motor failure | I21: Screw driver | J21: Súng bắn vít | K21: Shuang Ai | L21: POL-SDGS-0530 | M21: - | N21: - | O21: Common | P21: - | Q21: - | R21: - | S21: No Need | T21: - | U21: - | V21: Không cần hiệu chuẩn | W21: NG | X21: Line 1 | Z21: 24VDC, 0,8 ~ 1,6 Nm | AA21: Súng xanh | AB21: - | AC21: 0 | AF21: 1 | AG21: =INDEX(Sheet3!Y:Y,MATCH(D21,Sheet3!A:A,0)) -> 45233 | AH21: =INDEX(Sheet3!X:X,MATCH(D21,Sheet3!A:A,0)) -> HTV
A22: 21 | C22: NG | D22: PIE00028 | E22: Hỏng motor | F22: Motor failure | I22: Screw driver | J22: Súng bắn vít | K22: Shuang Ai | L22: POL-SDGS-0530 | M22: - | N22: - | O22: Common | P22: - | Q22: - | R22: - | S22: No Need | T22: - | U22: - | V22: Không cần hiệu chuẩn | W22: NG | X22: JIG | Z22: 24VDC, 0,8 ~ 1,6 Nm | AA22: Súng xanh | AB22: - | AC22: 0 | AF22: 1 | AG22: =INDEX(Sheet3!Y:Y,MATCH(D22,Sheet3!A:A,0)) -> 45233 | AH22: =INDEX(Sheet3!X:X,MATCH(D22,Sheet3!A:A,0)) -> HTV
A23: 22 | C23: NG | D23: PIE00029 | E23: Hỏng motor | F23: Motor failure | I23: Screw driver | J23: Súng bắn vít | K23: Shuang Ai | L23: POL-SDGS-0530 | M23: - | N23: - | O23: Common | P23: - | Q23: - | R23: - | S23: No Need | T23: - | U23: - | V23: Không cần hiệu chuẩn | W23: NG | X23: Line 10 | Z23: 24VDC, 0,8 ~ 1,6 Nm | AA23: Súng xanh | AB23: - | AC23: 0 | AF23: 1 | AG23: =INDEX(Sheet3!Y:Y,MATCH(D23,Sheet3!A:A,0)) -> 45233 | AH23: =INDEX(Sheet3!X:X,MATCH(D23,Sheet3!A:A,0)) -> HTV
A24: 23 | C24: NG | D24: PIE00030 | E24: Hỏng motor | F24: Motor failure | I24: Screw driver | J24: Súng bắn vít | K24: Shuang Ai | L24: POL-SDGS-0530 | M24: - | N24: - | O24: Common | P24: - | Q24: - | R24: - | S24: No Need | T24: - | U24: - | V24: Không cần hiệu chuẩn | W24: NG | X24: JIG | Z24: 24VDC, 0,8 ~ 1,6 Nm | AA24: Súng xanh | AB24: - | AC24: 0 | AF24: 1 | AG24: =INDEX(Sheet3!Y:Y,MATCH(D24,Sheet3!A:A,0)) -> 45233 | AH24: =INDEX(Sheet3!X:X,MATCH(D24,Sheet3!A:A,0)) -> HTV
A25: 24 | C25: NG | D25: PIE00031 | E25: Hỏng motor | F25: Motor failure | I25: Screw driver | J25: Súng bắn vít | K25: - | L25: POL-SDGS-0530 | M25: - | N25: - | O25: Common | P25: - | Q25: - | R25: - | S25: No Need | T25: - | U25: - | V25: Không cần hiệu chuẩn | W25: NG | X25: Line 1 | Z25: 24VDC, 0,8 ~ 1,6 Nm | AA25: Súng xanh | AB25: - | AC25: 0 | AF25: 1 | AG25: =INDEX(Sheet3!Y:Y,MATCH(D25,Sheet3!A:A,0)) -> 45233 | AH25: =INDEX(Sheet3!X:X,MATCH(D25,Sheet3!A:A,0)) -> HTV
A26: 25 | C26: NG | D26: PIE00032 | E26: Hỏng motor, lò xo | F26: Motor and spring failure | I26: Screw driver | J26: Súng bắn vít | K26: Shuang Ai | L26: POL-SDGS-0115 | M26: - | N26: - | O26: Common | P26: - | Q26: - | R26: - | S26: No Need | T26: - | U26: - | V26: Không cần hiệu chuẩn | W26: NG | X26: JIG | Z26: 24VDC, 0,1 ~ 1 Nm | AA26: Súng bắn vít nhỏ | AB26: - | AC26: 0 | AF26: 1 | AG26: =INDEX(Sheet3!Y:Y,MATCH(D26,Sheet3!A:A,0)) -> 45233 | AH26: =INDEX(Sheet3!X:X,MATCH(D26,Sheet3!A:A,0)) -> HTV
A27: 26 | C27: NG | D27: PIE00033 | E27: Hỏng motor, lò xo | F27: Motor and spring failure | I27: Screw driver | J27: Súng bắn vít | K27: Shuang Ai | L27: POL-SDGS-0115 | M27: - | N27: - | O27: Common | P27: - | Q27: - | R27: - | S27: No Need | T27: - | U27: - | V27: Không cần hiệu chuẩn | W27: NG | X27: REPAIR | Z27: 24VDC, 0,1 ~ 1 Nm | AA27: Súng bắn vít nhỏ | AB27: - | AC27: 0 | AF27: 1 | AG27: =INDEX(Sheet3!Y:Y,MATCH(D27,Sheet3!A:A,0)) -> 45233 | AH27: =INDEX(Sheet3!X:X,MATCH(D27,Sheet3!A:A,0)) -> HTV
A28: 27 | C28: NG | D28: PIE00034 | E28: Hỏng motor, lò xo | F28: Motor and spring failure | I28: Screw driver | J28: Súng bắn vít | K28: Shuang Ai | L28: POL-SDGS-0115 | M28: - | N28: - | O28: Common | P28: - | Q28: - | R28: - | S28: No Need | T28: - | U28: - | V28: Không cần hiệu chuẩn | W28: Scrap | X28: JIG | Z28: 24VDC, 0,1 ~ 1 Nm | AA28: Súng bắn vít nhỏ | AB28: - | AC28: 0 | AF28: 1 | AG28: =INDEX(Sheet3!Y:Y,MATCH(D28,Sheet3!A:A,0)) -> 45233 | AH28: =INDEX(Sheet3!X:X,MATCH(D28,Sheet3!A:A,0)) -> HTV
A29: 28 | C29: NG | D29: PIE00035 | E29: Hỏng motor, lò xo | F29: Motor and spring failure | I29: Screw driver | J29: Súng bắn vít | K29: Shuang Ai | L29: POL-SDGS-0115 | M29: - | N29: - | O29: Common | P29: - | Q29: - | R29: - | S29: No Need | T29: - | U29: - | V29: Không cần hiệu chuẩn | W29: NG | X29: JIG | Z29: 24VDC, 0,1 ~ 1 Nm | AA29: Súng bắn vít nhỏ | AB29: - | AC29: 0 | AF29: 1 | AG29: =INDEX(Sheet3!Y:Y,MATCH(D29,Sheet3!A:A,0)) -> 45233 | AH29: =INDEX(Sheet3!X:X,MATCH(D29,Sheet3!A:A,0)) -> HTV
A30: 29 | C30: NG | D30: PIE00036 | E30: Hỏng motor | F30: Motor failure | I30: - | J30: - | K30: - | L30: - | M30: - | N30: - | O30: - | P30: - | Q30: - | R30: - | S30: No Need | T30: - | U30: - | V30: . | W30: Scrap | X30: Chưa phân loại | Z30: - | AA30: Súng bắn vít nhỏ | AB30: - | AC30: 0 | AF30: 1 | AG30: =INDEX(Sheet3!Y:Y,MATCH(D30,Sheet3!A:A,0)) -> 45233 | AH30: =INDEX(Sheet3!X:X,MATCH(D30,Sheet3!A:A,0)) -> HTV
A31: 30 | C31: NG | D31: PIE00037 | E31: Hỏng motor, lò xo | F31: Motor and spring failure | I31: Screw driver | J31: Súng bắn vít | K31: Shuang Ai | L31: POL-SDGS-0115 | M31: - | N31: - | O31: Common | P31: - | Q31: - | R31: - | S31: No Need | T31: - | U31: - | V31: Không cần hiệu chuẩn | W31: NG | X31: Line 13 | Z31: - | AA31: Súng bắn vít nhỏ | AB31: - | AC31: 0 | AF31: 1 | AG31: =INDEX(Sheet3!Y:Y,MATCH(D31,Sheet3!A:A,0)) -> 45233 | AH31: =INDEX(Sheet3!X:X,MATCH(D31,Sheet3!A:A,0)) -> HTV
A32: 31 | C32: NG | D32: PIE00038 | E32: Hỏng motor | F32: Motor failure | I32: - | J32: - | K32: - | L32: - | M32: - | N32: - | O32: - | P32: - | Q32: - | R32: - | S32: No Need | T32: - | U32: - | V32: . | W32: Scrap | X32: Chưa phân loại | Z32: - | AA32: Súng bắn vít nhỏ | AB32: - | AC32: 0 | AF32: 1 | AG32: =INDEX(Sheet3!Y:Y,MATCH(D32,Sheet3!A:A,0)) -> 45233 | AH32: =INDEX(Sheet3!X:X,MATCH(D32,Sheet3!A:A,0)) -> HTV
A33: 32 | C33: Scrap | D33: PIE00047 | E33: Hỏng IC | F33: IC failure | I33: Barcode Scanner | J33: Súng Scan Barcode | K33: SYBLE | L33: XB-2178G | M33: - | N33: - | O33: Common | P33: - | Q33: - | R33: - | S33: No Need | T33: - | U33: - | V33: Không cần hiệu chuẩn | W33: Scrap | X33: JIG | Z33: Súng scan barcode 1D | AA33: - | AB33: - | AC33: 0 | AF33: 1 | AH33: =INDEX(Sheet3!X:X,MATCH(D33,Sheet3!A:A,0)) -> TS
A34: 33 | C34: NG | D34: PIE00056 | E34: nhiễu sóng,chập chờn | F34: Signal interference, intermittent | H34: Z:\FTP\PIE\MPVN Oder\MPVN NG - No use - Scrap Device\VIdeo NG\PIE00056.mp4 | I34: Signal Generator | J34: Máy tạo sóng dùng cho sản xuất | K34: LWDQGS | L34: TAG-101 | M34: 221105843 | N34: - | O34: Roland | P34: - | Q34: 51007 | R34: - | S34: External | T34: 2025-05-24 | U34: 2026-05-24 | V34: Hết hạn hiệu chuẩn | W34: NG | X34: JIG | Y34: Hiệu chuẩn ngoài | Z34: Máy tạo sóng | AA34: 20260515 Hiệu chuẩn NG (Lỗi: Chập chờn) | AB34: - | AC34: 0 | AF34: 1 | AH34: =INDEX(Sheet3!X:X,MATCH(D34,Sheet3!A:A,0)) -> TS
A35: 34 | C35: NG | D35: PIE00101 | E35: Hỏng motor, lò xo | F35: Motor and spring failure | G35: Z:\FTP\PIE\MPVN Oder\MPVN NG - No use - Scrap Device\Ảnh NG\súng trắng.png | I35: Screw driver | J35: Súng bắn vít | K35: Shuang Ai | L35: POL-SDGS-0115 | M35: - | N35: - | O35: Common | P35: - | Q35: 50655 | R35: - | S35: No Need | T35: - | U35: - | V35: Không cần hiệu chuẩn | W35: Scrap | X35: Chưa phân loại | Z35: 24VDC, 0,1 ~ 1 Nm | AA35: Súng bắn vít nhỏ | AB35: - | AC35: 0 | AF35: 1 | AH35: =INDEX(Sheet3!X:X,MATCH(D35,Sheet3!A:A,0)) -> TS
A36: 35 | C36: NG | D36: PIE00102 | E36: Hỏng motor, lò xo | F36: Motor and spring failure | G36: Z:\FTP\PIE\MPVN Oder\MPVN NG - No use - Scrap Device\Ảnh NG\súng trắng.png | I36: Screw driver | J36: Súng bắn vít | K36: Shuang Ai | L36: POL-SDGS-0115 | M36: - | N36: - | O36: Common | P36: - | Q36: - | R36: - | S36: No Need | T36: - | U36: - | V36: Không cần hiệu chuẩn | W36: Scrap | X36: Chưa phân loại | Z36: 24VDC, 0,1 ~ 1 Nm | AA36: Súng bắn vít nhỏ | AB36: - | AC36: 0 | AF36: 1 | AH36: =INDEX(Sheet3!X:X,MATCH(D36,Sheet3!A:A,0)) -> TS
A37: 36 | C37: NG | D37: PIE00103 | E37: Hỏng motor | F37: Motor failure | G37: Z:\FTP\PIE\MPVN Oder\MPVN NG - No use - Scrap Device\Ảnh NG\súng trắng.png | I37: - | J37: - | K37: - | L37: - | M37: - | N37: - | O37: - | P37: - | Q37: - | R37: - | S37: No Need | T37: - | U37: - | V37: . | W37: Scrap | X37: Chưa phân loại | Z37: - | AA37: Súng bắn vít nhỏ | AB37: - | AC37: 0 | AF37: 1 | AH37: =INDEX(Sheet3!X:X,MATCH(D37,Sheet3!A:A,0)) -> TS
A38: 37 | C38: NG | D38: PIE00104 | E38: Hỏng motor, lò xo | F38: Motor and spring failure | G38: Z:\FTP\PIE\MPVN Oder\MPVN NG - No use - Scrap Device\Ảnh NG\súng trắng.png | I38: Screw driver | J38: Súng bắn vít | K38: Shuang Ai | L38: POL-SDGS-0115 | M38: - | N38: - | O38: Common | P38: - | Q38: - | R38: - | S38: No Need | T38: - | U38: - | V38: Không cần hiệu chuẩn | W38: Scrap | X38: Chưa phân loại | Z38: 24VDC, 0,1 ~ 1 Nm | AA38: Súng bắn vít nhỏ | AB38: - | AC38: 0 | AF38: 1 | AH38: =INDEX(Sheet3!X:X,MATCH(D38,Sheet3!A:A,0)) -> TS
A39: 38 | C39: NG | D39: PIE00105 | E39: Hỏng motor | F39: Motor failure | G39: Z:\FTP\PIE\MPVN Oder\MPVN NG - No use - Scrap Device\Ảnh NG\súng trắng.png | I39: - | J39: - | K39: - | L39: - | M39: - | N39: - | O39: - | P39: - | Q39: - | R39: - | S39: No Need | T39: - | U39: - | V39: . | W39: Scrap | X39: Chưa phân loại | Z39: - | AA39: Súng bắn vít nhỏ | AB39: - | AC39: 0 | AF39: 1 | AH39: =INDEX(Sheet3!X:X,MATCH(D39,Sheet3!A:A,0)) -> TS
A40: 39 | C40: NG | D40: PIE00107 | E40: Hỏng motor | F40: Motor failure | G40: Z:\FTP\PIE\MPVN Oder\MPVN NG - No use - Scrap Device\Ảnh NG\súng trắng.png | I40: Screw driver | J40: Súng bắn vít | K40: - | L40: POL-SD2 | M40: - | N40: - | O40: Common | P40: - | Q40: 50871 | R40: - | S40: No Need | T40: - | U40: - | V40: Không cần hiệu chuẩn | W40: NG | X40: JIG | Z40: 24VDC, 0.6A | AA40: Súng Trắng | AB40: - | AC40: 0 | AF40: 1 | AH40: =INDEX(Sheet3!X:X,MATCH(D40,Sheet3!A:A,0)) -> TS
...

Sheet Sheet3
A1: Code | B1: Equipments name (Eng) | C1: Equipments name (Vie) | D1: Manufacturer | E1: Model of euqipment | F1: Equipment Serials | G1: TS serials | H1: Use for customer | I1: Use for model | J1: Description | K1: Calibration (Internal/Extenal) | L1: Calibration date | M1: Out of calibration date | N1: Status | O1: Link report | P1: Maintenance | Q1: Next date maintenance | R1: Actual | S1: Maintenance Status | T1: Q'ty | U1: Status | V1: Euipment No. | W1: FA No. | X1: Vendor name | Y1: Received date | Z1: Price (VND) | AA1: PR No./ Order date | AB1: Classify | AC1: Code PIE | AD1: Group name | AE1: Qty of item group | AF1: Picture | AG1: Column_33 | AH1: Remain days for next calibration | AI1: Current departments use | AJ1: Record giao nhận | AK1: History maintenance | AL1: Dữ liệu trước khi hủy mã | AM1: Year | AN1: Remark3 | AO1: Remark 4 | AP1: Column_42 | AQ1: Column_43 | AR1: Column_44 | AS1: STT | AT1: Column_46 | AU1: Trang_thai | AV1: T.gian giao | AW1: T.gian nhan | AX1: ID Người mượn | AY1: Tên người mượn | AZ1: Vị trí sử dụng | BA1: Chú thích | BB1: Vị trí ở phòng Jig | BC1: Công đoạn sử dụng | BD1: Last time | BE1: Tinh_trang | BF1: Link hinh anh | BG1: Ý kiến đóng góp | BH1: Xac_nhan | BI1: Báo cáo hiệu chuẩn | BJ1: Báo cáo bảo dưỡng | BK1: Trạng thái cấp phát | BL1: Số lượng theo thiết bị | BM1: LSGNTB_BEFORE | BN1: LSGNTB_INFOR | BO1: LSGNTB_HISTORY | BP1: LSCNHC_BEFORE | BQ1: LSCNHC_INFOR | BR1: LSCNHC_HISTORY | BS1: Trạng thái kiểm kê 1 | BT1: Ngày kiểm kê gần nhất | BU1: Trạng thái kiểm kê 2
A2: PIE00001 | N2: . | P2: No need | S2: - | T2: 1 | U2: Normal | X2: HTV | Y2: 45233 | Z2: VND 570,000 | AB2: EQ | AC2: PIE00001 | AE2: 24 | AF2: \\vnad\common\PIE\PIE STAFF 04 (Mr. Hoang)\2. Files, documents\File thiết bị\Hình ảnh\PIE00001.jpg | AG2: PIE00001 | AH2: .Hủy / Phế | AK2: PIE00001PIE00001Screw driverSúng bắn vítShuang AiPOL-SDGS-0115Common24VDC, 0,1 ~ 1 Nm | AL2: PIE00001Screw driverSúng bắn vítShuang AiPOL-SDGS-0115Common24VDC, 0,1 ~ 1 Nm | AM2: 23 | AO2: - | AP2: Đã kiểm kê 28/08/2026 | AS2: 1 | AU2: Chưa trả | AV2: 46262.649 | AW2: 46256.666 | AX2: 1526 | AY2: Nguyễn Thành Nam - PIE | AZ2: Line 14 | BA2: Súng bắn vít nhỏ | BD2: 46276.582 | BE2: Hủy / Phế | BF2: Jig_Equipment picture/PIE00001.jpg | BH2: Đúng | BK2: Tạm thời | BL2: 0 | BM2: Chưa trả***29/09/2025 21:50:49: 217_Phùng Huy Hoàng - PIE_Line 1 | BN2: Chưa trả***28/08/2026 15:35:07: 1526_Nguyễn Thành Nam - PIE_Line 14 | BO2: 07/2026 18:22:32;Chưa trả***16/07/2026 18:23:25: -__JIG_;Chưa trả***16/07/2026 18:23:25: 511_Trần Văn Thưởng - FA_REPAIR_;Đã nhận***18/07/2026 09:02:01;Đã nhận***18/07/2026 09:03:27;Chưa trả***18/07/2026 09:04:00: 511_Trần Văn Thưởng - FA_REPAIR_;Chưa trả***18/07/2026 09:06:37: 511_Trần Văn Thưởng - FA_REPAIR_;Đã nhận***18/07/2026 09:07:51;Đã nhận***18/07/2026 09:12:17;Đã nhận***18/07/2026 09:13:48;Chưa trả***18/07/2026 09:30:31: 511_Trần Văn Thưởng - FA_REPAIR_;Đã nhận***18/07/2026 09:44:42;Đã nhận***18/07/2026 09:59:12;Đã nhận***18/07/2026 10:18:12;Chưa trả***18/07/2026 10:51:26: 217_Phùng Huy Hoàng - PIE_Line 1_;Đã nhận***18/07/2026 10:51:31;Chưa trả***18/07/2026 10:51:33: -__JIG_;Chưa trả***18/07/2026 10:51:33: -__JIG_;Đã nhận***18/07/2026 11:09:05;Chưa trả***18/07/2026 11:15:53: -__JIG;Chưa trả***18/07/2026 11:15:53: 511_Trần Văn Thưởng - FA_REPAIR;Đã nhận***18/07/2026 11:18:01;Chưa trả***18/07/2026 11:19:02: 511_Trần Văn Thưởng - FA_REPAIR;Chưa trả***18/07/2026 11:19:02: 511_Trần Văn Thưởng - FA_REPAIR_.-zvdfjh;Đã nhận***18/07/2026 11:34:38_;Chưa trả***18/07/2026 11:34:53: l;'__Line 14;Đã nhận***18/07/2026 11:35:04;Đã nhận***18/07/2026 11:35:04_r;Đã nhận***18/07/2026 11:35:04_rgf;Đã nhận***18/07/2026 11:36:36_;Chưa trả***18/07/2026 11:36:37: -__JIG;Chưa trả***18/07/2026 11:36:37: 511_Trần Văn Thưởng - FA_REPAIR;Chưa trả***18/07/2026 11:39:01: 511_Trần Văn Thưởng - FA_REPAIR;Đã nhận***22/08/2026 15:58:42;Chưa trả***28/08/2026 15:35:07: 1526_Nguyễn Thành Nam - PIE_Line 14 | BQ2: 11/12/2025 13:43:24 : No Need - _ _ | BR2: 1:37: 511_Trần Văn Thưởng - FA_REPAIR;Chưa trả***16/07/2026 18:08:37: 511_Trần Văn Thưởng - FA_REPAIR;Đã nhận***16/07/2026 18:09:27;Chưa trả***16/07/2026 18:09:47: -__JIG;Chưa trả***16/07/2026 18:09:47: 511_Trần Văn Thưởng - FA_REPAIR;Chưa trả***16/07/2026 18:09:47: 511_Trần Văn Thưởng - FA_REPAIRCố định;Đã nhận***16/07/2026 18:18:37;Chưa trả***16/07/2026 18:19:28: -__JIG_Ghi chú:;Chưa trả***16/07/2026 18:19:28: 511_Trần Văn Thưởng - FA_REPAIR_Ghi chú:;Đã nhận***16/07/2026 18:22:32;Chưa trả***16/07/2026 18:23:25: -__JIG_;Chưa trả***16/07/2026 18:23:25: 511_Trần Văn Thưởng - FA_REPAIR_;Đã nhận***18/07/2026 09:02:01;Đã nhận***18/07/2026 09:03:27;Chưa trả***18/07/2026 09:04:00: 511_Trần Văn Thưởng - FA_REPAIR_;Chưa trả***18/07/2026 09:06:37: 511_Trần Văn Thưởng - FA_REPAIR_;Đã nhận***18/07/2026 09:07:51;Đã nhận***18/07/2026 09:12:17;Đã nhận***18/07/2026 09:13:48;Chưa trả***18/07/2026 09:30:31: 511_Trần Văn Thưởng - FA_REPAIR_;Đã nhận***18/07/2026 09:44:42;Đã nhận***18/07/2026 09:59:12;Đã nhận***18/07/2026 10:18:12;Chưa trả***18/07/2026 10:51:26: 217_Phùng Huy Hoàng - PIE_Line 1_;Đã nhận***18/07/2026 10:51:31;Chưa trả***18/07/2026 10:51:33: -__JIG_;Chưa trả***18/07/2026 10:51:33: -__JIG_;Đã nhận***18/07/2026 11:09:05;Chưa trả***18/07/2026 11:15:53: -__JIG;Chưa trả***18/07/2026 11:15:53: 511_Trần Văn Thưởng - FA_REPAIR;Đã nhận***18/07/2026 11:18:01;Chưa trả***18/07/2026 11:19:02: 511_Trần Văn Thưởng - FA_REPAIR;Chưa trả***18/07/2026 11:19:02: 511_Trần Văn Thưởng - FA_REPAIR_.-zvdf | BS2: Đã kiểm kê | BT2: 46262 | BU2: Hủy / Phế
A3: PIE00002 | B3: Screw driver | C3: Súng bắn vít | D3: Shuang Ai | E3: POL-SDGS-0115 | H3: Common | J3: 24VDC, 0,1 ~ 1 Nm | K3: No Need | N3: - | P3: No need | S3: - | T3: 1 | U3: Normal | X3: HTV | Y3: 45233 | Z3: VND 570,000 | AB3: EQ | AC3: PIE00002 | AF3: \\vnad\common\PIE\PIE STAFF 04 (Mr. Hoang)\2. Files, documents\File thiết bị\Hình ảnh\PIE00002.jpg | AG3: PIE00002 | AK3: PIE00002Screw driverSúng bắn vítShuang AiPOL-SDGS-0115Common24VDC, 0,1 ~ 1 Nm | AM3: 23 | AO3: Screw driver | AP3: Đã kiểm kê 14/07/2026 | AS3: 2 | AU3: Chưa trả | AV3: 46217.8 | AW3: 46003.365 | AX3: 676 | AY3: Hoàng Văn Mạnh - FA | AZ3: REPAIR | BA3: Súng bắn vít nhỏ | BD3: 46217.8 | BE3: Hủy / Phế | BF3: Jig_Equipment picture/PIE00002.jpg | BH3: Đúng | BK3: Cố định | BL3: 273 | BM3: 45929.36730324074 | BN3: Chưa trả***14/07/2026 19:11:56: 676_Hoàng Văn Mạnh - FA_REPAIR | BO3: Đã nhận***29/09/2025 08:48:55: 1414_Lê Hồng Quang - FA_LINE123;Đã nhận***29/09/2025 08:50:07: 1414_Lê Hồng Quang - FA_LINE123;Đã nhận***07/11/2025 11:09:15;Chưa trả***12/11/2025 13:38:29: -__JIG;Đã nhận***12/11/2025 13:45:18;Đã nhận***12/11/2025 14:12:10;Đã nhận***12/11/2025 14:29:30;Chưa trả***12/11/2025 14:49:57: -__JIG;Đã nhận***12/11/2025 15:38:24;Đã nhận***13/11/2025 10:48:50;Đã nhận***13/11/2025 11:19:36;Đã nhận***13/11/2025 11:32:01;Đã nhận***13/11/2025 11:32:05;Chưa trả***13/11/2025 15:03:00: 217_Phùng Huy Hoàng - PIE_WH;Chưa trả***13/11/2025 15:31:14: 217_Phùng Huy Hoàng - PIE_PIE;Chưa trả***14/11/2025 15:28:39: 217_Phùng Huy Hoàng - PIE_Line 13;Chưa trả***14/11/2025 15:28:40: 1414_Lê Hồng Quang - FA_Line 8;Chưa trả***14/11/2025 15:28:40: 1414_Lê Hồng Quang - FA_MI;Chưa trả***09/07/2026 08:23:43: 1276_Nguyễn Hải Văn - PIE_PIE;Chưa trả***14/07/2026 19:11:56: 1276_Nguyễn Hải Văn - PIE_PIE;Chưa trả***14/07/2026 19:11:56: 676_Hoàng Văn Mạnh - FA_REPAIR | BQ3: 11/12/2025 13:29:12 : No Need - _ _ | BS3: Đã kiểm kê | BT3: 46217 | BU3: Hủy / Phế
A4: PIE00003 | B4: Screw driver | C4: Súng bắn vít | D4: Shuang Ai | E4: POL-SDGS-0115 | H4: Common | J4: 24VDC, 0,1 ~ 1 Nm | K4: No Need | N4: - | P4: No need | S4: - | T4: 1 | U4: Normal | V4: 50662 | X4: TS | AB4: EQ | AC4: PIE00003 | AF4: \\vnad\common\PIE\PIE STAFF 04 (Mr. Hoang)\2. Files, documents\File thiết bị\Hình ảnh\PIE00003.jpg | AG4: PIE00003 | AK4: PIE00003Screw driverSúng bắn vítShuang AiPOL-SDGS-0115Common24VDC, 0,1 ~ 1 Nm | AM4: 23 | AO4: Screw driver | AP4: Đã kiểm kê 22/08/2026 | AS4: 3 | AU4: Đã nhận | AV4: 46241.45 | AW4: 46256.666 | AX4: - | AZ4: JIG | BA4: Súng bắn vít nhỏ | BD4: 46256.667 | BE4: Hủy / Phế | BF4: Jig_Equipment picture/PIE00003.jpg | BH4: . | BL4: 273 | BM4: 45929.37625 | BN4: Đã nhận***22/08/2026 15:58:41 | BO4: Đã nhận***29/09/2025 08:56:39: 1414_Lê Hồng Quang - FA_LINE123;Đã nhận***29/09/2025 08:56:43: 1414_Lê Hồng Quang - FA_LINE123;Đã nhận***29/09/2025 09:01:43: 1414_Lê Hồng Quang - FA_LINE123;Đã nhận***29/09/2025 09:01:48: 1414_Lê Hồng Quang - FA_LINE123;Đã nhận***29/09/2025 09:01:50: 1414_Lê Hồng Quang - FA_LINE123;Chưa trả***07/11/2025 11:19:54: -__-;Chưa trả***12/11/2025 13:38:33: -__JIG;Đã nhận***12/11/2025 14:12:11;Đã nhận***12/11/2025 15:38:25;Đã nhận***13/11/2025 10:48:51;Đã nhận***13/11/2025 11:32:02;Chưa trả***13/11/2025 15:03:00: 217_Phùng Huy Hoàng - PIE_WH;Chưa trả***13/11/2025 15:31:14: 217_Phùng Huy Hoàng - PIE_PIE;Chưa trả***14/11/2025 15:28:39: 217_Phùng Huy Hoàng - PIE_Line 13;Chưa trả***14/11/2025 15:28:40: 1414_Lê Hồng Quang - FA_Line 8;Chưa trả***14/11/2025 15:28:40: 1414_Lê Hồng Quang - FA_MI;Đã nhận***15/12/2025 15:58:36;Đã nhận***26/12/2025 15:15:20;Đã nhận***18/03/2026 08:48:57;Chưa trả***14/07/2026 15:21:35: 1526_Nguyễn Thành Nam - PIE_Line 5;Chưa trả***07/08/2026 10:41:00: 1526_Nguyễn Thành Nam - PIE_Line 12;Chưa trả***07/08/2026 10:47:51: 1526_Nguyễn Thành Nam - PIE_Line 12;Đã nhận***22/08/2026 15:58:41 | BQ4: 11/12/2025 13:42:37 : No Need - _ _ | BS4: Đã kiểm kê | BT4: 46256 | BU4: Hủy / Phế
A5: PIE00004 | B5: Screw driver | C5: Súng bắn vít | D5: Shuang Ai | E5: POL-SDGS-0115 | H5: Common | J5: 24VDC, 0,1 ~ 1 Nm | K5: No Need | N5: - | P5: No need | S5: - | T5: 1 | U5: Normal | X5: HTV | Y5: 45233 | Z5: VND 570,000 | AB5: EQ | AC5: PIE00004 | AF5: \\vnad\common\PIE\PIE STAFF 04 (Mr. Hoang)\2. Files, documents\File thiết bị\Hình ảnh\PIE00004.jpg | AG5: PIE00004 | AK5: PIE00004Screw driverSúng bắn vítShuang AiPOL-SDGS-0115Common24VDC, 0,1 ~ 1 Nm | AM5: 23 | AO5: Screw driver | AP5: Đã kiểm kê 26/12/2025 | AS5: 4 | AU5: Đã nhận | AV5: 45975.645 | AW5: 46017.636 | AX5: - | AZ5: JIG | BA5: Súng bắn vít nhỏ | BD5: 46017.637 | BE5: NG | BF5: Jig_Equipment picture/PIE00004.jpg | BH5: Đúng | BL5: 273 | BM5: 45929.37774305556 | BN5: Đã nhận***26/12/2025 15:15:20 | BO5: Đã nhận***29/09/2025 09:03:57: 1414_Lê Hồng Quang - FA_LL;Đã nhận***29/09/2025 09:03:59: 1414_Lê Hồng Quang - FA_LL;Chưa trả***12/11/2025 13:38:29: -__JIG;Đã nhận***12/11/2025 14:12:11;Đã nhận***12/11/2025 15:38:32;Đã nhận***13/11/2025 10:48:51;Đã nhận***13/11/2025 11:19:36;Đã nhận***13/11/2025 11:32:02;Chưa trả***13/11/2025 13:27:49: 217_Phùng Huy Hoàng - PIE_Line 3;Chưa trả***13/11/2025 15:03:01: 217_Phùng Huy Hoàng - PIE_WH;Chưa trả***13/11/2025 15:31:15: 217_Phùng Huy Hoàng - PIE_PIE;Chưa trả***14/11/2025 15:28:39: 217_Phùng Huy Hoàng - PIE_Line 13;Chưa trả***14/11/2025 15:28:48: 1414_Lê Hồng Quang - FA_Line 8;Đã nhận***26/12/2025 15:15:20 | BQ5: 11/12/2025 13:29:12 : No Need - _ _ | BS5: Đã kiểm kê | BT5: 46017 | BU5: NG
A6: PIE00005 | B6: Screw driver | C6: Súng bắn vít | D6: Shuang Ai | E6: POL-SDGS-0530 | H6: Common | J6: 24VDC, 0,8 ~ 1,6 Nm | K6: No Need | N6: - | P6: No need | S6: - | T6: 1 | U6: Normal | X6: HTV | Y6: 45233 | Z6: VND 580,000 | AB6: EQ | AC6: PIE00005 | AF6: \\vnad\common\PIE\PIE STAFF 04 (Mr. Hoang)\2. Files, documents\File thiết bị\Hình ảnh\PIE00005.jpg | AG6: PIE00005 | AK6: PIE00005Screw driverSúng bắn vítShuang AiPOL-SDGS-0530Common24VDC, 0,8 ~ 1,6 Nm | AM6: 23 | AO6: Screw driver | AP6: Đã kiểm kê 02/06/2026 | AS6: 5 | AU6: Đã nhận | AV6: 45975.645 | AW6: 46175.582 | AX6: - | AZ6: JIG | BD6: 46185.432 | BE6: NG | BF6: Jig_Equipment picture/PIE00005.jpg | BH6: Đúng | BL6: 273 | BM6: 45929.384421296294 | BN6: Đã nhận***02/06/2026 13:58:21 | BO6: Đã nhận***29/09/2025 09:06:56: __;Đã nhận***29/09/2025 09:06:58: __;Đã nhận***29/09/2025 09:12:57: __;Đã nhận***29/09/2025 09:13:00: __;Đã nhận***29/09/2025 09:13:04: __;Đã nhận***29/09/2025 09:13:06: __;Đã nhận***29/09/2025 09:13:07: __;Đã nhận***29/09/2025 09:13:10: __;Đã nhận***29/09/2025 09:13:12: __;Đã nhận***29/09/2025 09:13:15: __;Đã nhận***29/09/2025 09:13:19: __;Đã nhận***29/09/2025 09:13:22: __;Đã nhận***29/09/2025 09:13:25: __;Đã nhận***29/09/2025 09:13:27: __;Đã nhận***29/09/2025 09:13:31: __;Đã nhận***29/09/2025 09:13:34: __;Đã nhận***29/09/2025 09:13:37: __;Chưa trả***12/11/2025 13:38:27: -__JIG;Đã nhận***12/11/2025 14:12:13;Đã nhận***12/11/2025 14:50:03;Đã nhận***13/11/2025 10:48:52;Đã nhận***13/11/2025 11:19:37;Đã nhận***13/11/2025 11:32:03;Chưa trả***13/11/2025 15:03:01: 217_Phùng Huy Hoàng - PIE_WH;Chưa trả***13/11/2025 15:31:15: 217_Phùng Huy Hoàng - PIE_PIE;Chưa trả***14/11/2025 15:28:39: 217_Phùng Huy Hoàng - PIE_Line 13;Đã nhận***15/12/2025 14:09:36;Đã nhận***15/12/2025 14:09:37;Đã nhận***13/02/2026 08:39:58;Đã nhận***18/03/2026 08:48:57;Đã nhận***02/06/2026 13:58:21 | BQ6: 11/12/2025 13:29:12 : No Need - _ _ | BS6: Đã kiểm kê | BT6: 46175 | BU6: NG
A7: PIE00006 | B7: Screw driver | C7: Súng bắn vít | D7: Shuang Ai | E7: POL-SDGS-0530 | H7: Common | J7: 24VDC, 0,8 ~ 1,6 Nm | K7: No Need | N7: - | P7: No need | S7: - | T7: 1 | U7: Normal | X7: HTV | Y7: 45233 | Z7: VND 580,000 | AB7: EQ | AC7: PIE00006 | AF7: \\vnad\common\PIE\PIE STAFF 04 (Mr. Hoang)\2. Files, documents\File thiết bị\Hình ảnh\PIE00006.jpg | AG7: PIE00006 | AK7: PIE00006Screw driverSúng bắn vítShuang AiPOL-SDGS-0530Common24VDC, 0,8 ~ 1,6 Nm | AM7: 23 | AO7: Screw driver | AP7: Đã kiểm kê 17/06/2026 | AS7: 6 | AU7: Chưa trả | AV7: 46190.584 | AW7: 45974.472 | AX7: 884 | AY7: Nguyễn Tuấn Anh - PIE | AZ7: Line 9 | BA7: Súng xanh | BD7: 46190.584 | BE7: Hủy / Phế | BF7: Jig_Equipment picture/PIE00006.jpg | BH7: Đúng | BL7: 273 | BN7: Chưa trả***17/06/2026 14:00:41: 884_Nguyễn Tuấn Anh - PIE_Line 9 | BO7: ;Đã nhận***13/11/2025 11:19:35;Chưa trả***17/06/2026 14:00:41: 884_Nguyễn Tuấn Anh - PIE_Line 9 | BS7: Đã kiểm kê | BT7: 46190 | BU7: Hủy / Phế
A8: PIE00007 | B8: Screw driver | C8: Súng bắn vít | D8: Shuang Ai | E8: POL-SDGS-0530 | H8: Common | J8: 24VDC, 0,8 ~ 1,6 Nm | K8: No Need | N8: - | P8: No need | S8: - | T8: 1 | U8: Normal | X8: HTV | Y8: 45233 | Z8: VND 580,000 | AB8: EQ | AC8: PIE00007 | AF8: \\vnad\common\PIE\PIE STAFF 04 (Mr. Hoang)\2. Files, documents\File thiết bị\Hình ảnh\PIE00007.jpg | AG8: PIE00007 | AK8: PIE00007Screw driverSúng bắn vítShuang AiPOL-SDGS-0530Common24VDC, 0,8 ~ 1,6 Nm | AM8: 23 | AO8: Screw driver | AP8: Đã kiểm kê 28/08/2026 | AS8: 7 | AU8: Chưa trả | AV8: 46262.649 | AW8: 46017.66 | AX8: 1526 | AY8: Nguyễn Thành Nam - PIE | AZ8: Line 14 | BA8: Súng xanh | BD8: 46262.652 | BE8: NG | BF8: Jig_Equipment picture/PIE00007.jpg | BH8: Đúng | BL8: 273 | BN8: Chưa trả***28/08/2026 15:35:07: 1526_Nguyễn Thành Nam - PIE_Line 14 | BO8: ;Đã nhận***26/12/2025 15:15:19;Đã nhận***26/12/2025 15:50:49;Chưa trả***28/08/2026 15:35:07: 1526_Nguyễn Thành Nam - PIE_Line 14 | BS8: Đã kiểm kê | BT8: 46262 | BU8: NG
A9: PIE00008 | B9: Screw driver | C9: Súng bắn vít | D9: Shuang Ai | E9: POL-SDGS-0115 | H9: Common | J9: 24VDC, 0,1 ~ 1 Nm | K9: No Need | N9: - | P9: No need | S9: - | T9: 1 | U9: Normal | V9: 50661 | X9: HTV | AB9: EQ | AC9: PIE00008 | AF9: \\vnad\common\PIE\PIE STAFF 04 (Mr. Hoang)\2. Files, documents\File thiết bị\Hình ảnh\PIE00008.jpg | AG9: PIE00008 | AK9: PIE00008Screw driverSúng bắn vítShuang AiPOL-SDGS-0115Common24VDC, 0,1 ~ 1 Nm | AM9: 23 | AO9: Screw driver | AP9: Đã kiểm kê 12/12/2025 | AS9: 8 | AU9: Đã nhận | AV9: 45838.4 | AW9: 46003.381 | AX9: - | AZ9: JIG | BA9: Súng bắn vít nhỏ | BD9: 46003.381 | BE9: Hủy / Phế | BF9: Jig_Equipment picture/PIE00008.jpg | BH9: Đúng | BL9: 273 | BN9: Đã nhận***12/12/2025 09:08:36 | BO9: ;Đã nhận***12/12/2025 09:08:36 | BS9: Đã kiểm kê | BT9: 46003 | BU9: Hủy / Phế
A10: PIE00009 | N10: . | P10: No need | S10: - | T10: 1 | U10: Normal | X10: HTV | Y10: 45233 | Z10: VND 580,000 | AB10: EQ | AC10: PIE00009 | AF10: \\vnad\common\PIE\PIE STAFF 04 (Mr. Hoang)\2. Files, documents\File thiết bị\Hình ảnh\PIE00009.jpg | AG10: PIE00009 | AH10: .Hủy / Phế | AK10: PIE00009PIE00009Screw driverSúng bắn vítShuang AiPOL-SDGS-0530Common24VDC, 0,8 ~ 1,6 Nm | AL10: PIE00009Screw driverSúng bắn vítShuang AiPOL-SDGS-0530Common24VDC, 0,8 ~ 1,6 Nm | AM10: 23 | AO10: - | AP10: Đã kiểm kê 26/12/2025 | AS10: 9 | AU10: Đã nhận | AV10: 45838.381 | AW10: 46017.66 | AX10: - | AZ10: JIG | BA10: Súng xanh | BD10: 46017.662 | BE10: Hủy / Phế | BF10: Jig_Equipment picture/PIE00009.jpg | BH10: Đúng | BL10: 0 | BN10: Đã nhận***26/12/2025 15:50:49 | BO10: ;Đã nhận***26/12/2025 15:50:48;Đã nhận***26/12/2025 15:50:49 | BS10: Đã kiểm kê | BT10: 46017 | BU10: Hủy / Phế
A11: PIE00010 | B11: Screw driver | C11: Súng bắn vít | D11: Shuang Ai | E11: POL-SDGS-0530 | H11: Common | J11: 24VDC, 0,8 ~ 1,6 Nm | K11: No Need | N11: - | P11: No need | S11: - | T11: 1 | U11: Normal | X11: HTV | Y11: 45233 | Z11: VND 580,000 | AB11: EQ | AC11: PIE00010 | AF11: \\vnad\common\PIE\PIE STAFF 04 (Mr. Hoang)\2. Files, documents\File thiết bị\Hình ảnh\PIE00010.jpg | AG11: PIE00010 | AK11: PIE00010Screw driverSúng bắn vítShuang AiPOL-SDGS-0530Common24VDC, 0,8 ~ 1,6 Nm | AM11: 23 | AO11: Screw driver | AP11: Đã kiểm kê 24/06/2026 | AS11: 10 | AU11: Đã nhận | AV11: 46119.376 | AW11: 46197.368 | AX11: - | AZ11: JIG | BA11: Súng xanh | BD11: 46197.368 | BE11: NG | BF11: Jig_Equipment picture/PIE00010.jpg | BH11: Đúng | BL11: 273 | BN11: Đã nhận***24/06/2026 08:50:00 | BO11: ;Chưa trả***07/04/2026 09:00:57: 837_Chu Tiến Dũng - PIE_Line 1;Đã nhận***24/06/2026 08:50:00 | BS11: Đã kiểm kê | BT11: 46197 | BU11: NG
A12: PIE00011 | B12: Screw driver | C12: Súng bắn vít | D12: Shuang Ai | E12: POL-SDGS-0530 | H12: Common | J12: 24VDC, 0,8 ~ 1,6 Nm | K12: No Need | N12: - | P12: No need | S12: - | T12: 1 | U12: Normal | X12: HTV | Y12: 45233 | Z12: VND 580,000 | AB12: EQ | AC12: PIE00011 | AF12: \\vnad\common\PIE\PIE STAFF 04 (Mr. Hoang)\2. Files, documents\File thiết bị\Hình ảnh\PIE00011.jpg | AG12: PIE00011 | AK12: PIE00011Screw driverSúng bắn vítShuang AiPOL-SDGS-0530Common24VDC, 0,8 ~ 1,6 Nm | AM12: 23 | AO12: Screw driver | AP12: Đã kiểm kê 19/01/2026 | AS12: 11 | AU12: Đã nhận | AV12: 45853.373 | AW12: 46041.39 | AX12: - | AZ12: JIG | BA12: Súng xanh | BD12: 46041.394 | BE12: NG | BF12: Jig_Equipment picture/PIE00011.jpg | BH12: Đúng | BL12: 273 | BN12: Đã nhận***19/01/2026 09:22:08 | BO12: ;Đã nhận***19/01/2026 09:22:08 | BS12: Đã kiểm kê | BT12: 46041 | BU12: NG
A13: PIE00012 | B13: Screw driver | C13: Súng bắn vít | D13: Shuang Ai | E13: POL-SDGS-0530 | H13: Common | J13: 24VDC, 0,8 ~ 1,6 Nm | K13: No Need | N13: - | P13: No need | S13: - | T13: 1 | U13: Normal | X13: HTV | Y13: 45233 | Z13: VND 580,000 | AB13: EQ | AC13: PIE00012 | AF13: \\vnad\common\PIE\PIE STAFF 04 (Mr. Hoang)\2. Files, documents\File thiết bị\Hình ảnh\PIE00012.jpg | AG13: PIE00012 | AK13: PIE00012Screw driverSúng bắn vítShuang AiPOL-SDGS-0530Common24VDC, 0,8 ~ 1,6 Nm | AM13: 23 | AO13: Screw driver | AP13: Đã kiểm kê 06/11/2025 | AS13: 12 | AZ13: JIG | BA13: Súng xanh | BD13: 45967.59 | BE13: Bình thường | BF13: Jig_Equipment picture/PIE00012.jpg | BH13: Đúng | BL13: 273 | BN13: *** | BO13: ;*** | BS13: Đã kiểm kê | BT13: 45967 | BU13: Cần phải kiểm kê
A14: PIE00013 | N14: . | P14: No need | S14: - | T14: 1 | U14: Normal | X14: HTV | Y14: 45233 | Z14: VND 570,000 | AB14: EQ | AC14: PIE00013 | AF14: \\vnad\common\PIE\PIE STAFF 04 (Mr. Hoang)\2. Files, documents\File thiết bị\Hình ảnh\PIE00013.jpg | AG14: PIE00013 | AH14: .Hủy / Phế | AK14: PIE00013PIE00013Screw driverSúng bắn vítShuang AiPOL-SDGS-0115Common24VDC, 0,1 ~ 1 Nm | AL14: PIE00013Screw driverSúng bắn vítShuang AiPOL-SDGS-0115Common24VDC, 0,1 ~ 1 Nm | AM14: 23 | AO14: - | AS14: 13 | AZ14: - | BA14: Súng bắn vít nhỏ | BE14: Hủy / Phế | BF14: Jig_Equipment picture/PIE00013.jpg | BH14: Đúng | BL14: 0 | BU14: Hủy / Phế
A15: PIE00014 | B15: Screw driver | C15: Súng bắn vít | D15: Shuang Ai | E15: POL-SDGS-0115 | H15: Common | J15: 24VDC, 0,1 ~ 1 Nm | K15: No Need | N15: - | P15: No need | S15: - | T15: 1 | U15: Normal | X15: HTV | Y15: 45233 | Z15: VND 570,000 | AB15: EQ | AC15: PIE00014 | AF15: \\vnad\common\PIE\PIE STAFF 04 (Mr. Hoang)\2. Files, documents\File thiết bị\Hình ảnh\PIE00014.jpg | AG15: PIE00014 | AK15: PIE00014Screw driverSúng bắn vítShuang AiPOL-SDGS-0115Common24VDC, 0,1 ~ 1 Nm | AM15: 23 | AO15: Screw driver | AP15: Đã kiểm kê 26/06/2026 | AS15: 14 | AU15: Chưa trả | AV15: 46199.565 | AW15: 46006.666 | AX15: 1526 | AY15: Nguyễn Thành Nam - PIE | AZ15: Line 11 | BA15: Súng bắn vít nhỏ | BD15: 46199.57 | BE15: NG | BF15: Jig_Equipment picture/PIE00014.jpg | BH15: Đúng | BL15: 273 | BN15: Chưa trả***26/06/2026 13:34:00: 1526_Nguyễn Thành Nam - PIE_Line 11 | BO15: ;***;Chưa trả***26/06/2026 13:34:00: 1526_Nguyễn Thành Nam - PIE_Line 11 | BS15: Đã kiểm kê | BT15: 46199 | BU15: NG
A16: PIE00015 | N16: . | P16: No need | S16: - | T16: 1 | U16: Normal | X16: HTV | Y16: 45233 | Z16: VND 570,000 | AB16: EQ | AC16: PIE00015 | AF16: \\vnad\common\PIE\PIE STAFF 04 (Mr. Hoang)\2. Files, documents\File thiết bị\Hình ảnh\PIE00015.jpg | AG16: PIE00015 | AH16: .Hủy / Phế | AK16: PIE00015PIE00015Screw driverSúng bắn vítShuang AiPOL-SDGS-0115Common24VDC, 0,1 ~ 1 Nm | AL16: PIE00015Screw driverSúng bắn vítShuang AiPOL-SDGS-0115Common24VDC, 0,1 ~ 1 Nm | AM16: 23 | AO16: - | AP16: Đã kiểm kê 12/01/2026 | AS16: 15 | AU16: Đã nhận | AW16: 46034.66 | AX16: - | AZ16: JIG | BA16: Súng bắn vít nhỏ | BD16: 46034.663 | BE16: Hủy / Phế | BF16: Jig_Equipment picture/PIE00015.jpg | BH16: Đúng | BL16: 0 | BN16: Đã nhận***12/01/2026 15:50:15 | BO16: ;Đã nhận***12/01/2026 15:50:09;Đã nhận***12/01/2026 15:50:11;Đã nhận***12/01/2026 15:50:15 | BS16: Đã kiểm kê | BT16: 46034 | BU16: Hủy / Phế
A17: PIE00016 | N17: . | P17: No need | S17: - | T17: 1 | U17: Normal | X17: HTV | Y17: 45233 | Z17: VND 570,000 | AB17: EQ | AC17: PIE00016 | AF17: \\vnad\common\PIE\PIE STAFF 04 (Mr. Hoang)\2. Files, documents\File thiết bị\Hình ảnh\PIE00016.jpg | AG17: PIE00016 | AH17: .Hủy / Phế | AK17: PIE00016PIE00016Screw driverSúng bắn vítShuang AiPOL-SDGS-0115Common24VDC, 0,1 ~ 1 Nm | AL17: PIE00016Screw driverSúng bắn vítShuang AiPOL-SDGS-0115Common24VDC, 0,1 ~ 1 Nm | AM17: 23 | AO17: - | AS17: 16 | AU17: Đã nhận | AV17: 45836.82 | AW17: 45836.82 | AX17: - | AZ17: JIG | BA17: Súng bắn vít nhỏ | BD17: 46037.266 | BE17: Hủy / Phế | BF17: Jig_Equipment picture/PIE00016.jpg | BH17: Đúng | BL17: 0 | BN17: Đã nhận***28/06/2025 19:40:29 | BU17: Hủy / Phế
A18: PIE00017 | B18: Screw driver | C18: Súng bắn vít | D18: Shuang Ai | E18: POL-SDGS-0530 | H18: Common | J18: 24VDC, 0,8 ~ 1,6 Nm | K18: No Need | N18: - | P18: No need | S18: - | T18: 1 | U18: Normal | X18: HTV | Y18: 45233 | Z18: VND 580,000 | AB18: EQ | AC18: PIE00017 | AF18: \\vnad\common\PIE\PIE STAFF 04 (Mr. Hoang)\2. Files, documents\File thiết bị\Hình ảnh\PIE00017.jpg | AG18: PIE00017 | AK18: PIE00017Screw driverSúng bắn vítShuang AiPOL-SDGS-0530Common24VDC, 0,8 ~ 1,6 Nm | AM18: 23 | AO18: Screw driver | AP18: Đã kiểm kê 06/11/2025 | AS18: 17 | AU18: Đã nhận | AW18: 45839.44 | AX18: - | AZ18: - | BA18: Súng xanh | BD18: 45967.591 | BE18: NG | BF18: Jig_Equipment picture/PIE00017.jpg | BH18: Đúng | BL18: 273 | BN18: Đã nhận***01/07/2025 10:33:53 | BS18: Đã kiểm kê | BT18: 45967 | BU18: NG
A19: PIE00018 | B19: Screw driver | C19: Súng bắn vít | D19: Shuang Ai | E19: POL-SDGS-0530 | H19: Common | J19: 24VDC, 0,8 ~ 1,6 Nm | K19: No Need | N19: - | P19: No need | S19: - | T19: 1 | U19: Normal | X19: HTV | Y19: 45233 | Z19: VND 580,000 | AB19: EQ | AC19: PIE00018 | AF19: \\vnad\common\PIE\PIE STAFF 04 (Mr. Hoang)\2. Files, documents\File thiết bị\Hình ảnh\PIE00018.jpg | AG19: PIE00018 | AK19: PIE00018Screw driverSúng bắn vítShuang AiPOL-SDGS-0530Common24VDC, 0,8 ~ 1,6 Nm | AM19: 23 | AO19: Screw driver | AP19: Đã kiểm kê 07/04/2026 | AS19: 18 | AU19: Chưa trả | AV19: 46119.376 | AX19: 837 | AY19: Chu Tiến Dũng - PIE | AZ19: Line 1 | BA19: Súng xanh | BD19: 46119.376 | BE19: NG | BF19: Jig_Equipment picture/PIE00018.jpg | BH19: Đúng | BL19: 273 | BN19: Chưa trả***07/04/2026 09:01:30: 837_Chu Tiến Dũng - PIE_Line 1 | BO19: ;***;Chưa trả***07/04/2026 09:01:30: 837_Chu Tiến Dũng - PIE_Line 1 | BS19: Đã kiểm kê | BT19: 46119 | BU19: NG
A20: PIE00019 | B20: Soldering Station | C20: Máy hàn | D20: HAKO | E20: SLD 936 | H20: Common | J20: 220V, 60W | K20: No Need | N20: - | P20: No need | S20: - | T20: 1 | U20: Normal | V20: 50398 | X20: TS | AB20: EQ | AC20: PIE00019 | AF20: \\vnad\common\PIE\PIE STAFF 04 (Mr. Hoang)\2. Files, documents\File thiết bị\Hình ảnh\PIE00019.jpg | AG20: PIE00019 | AK20: PIE00019Soldering StationMáy hànHAKOSLD 936Common220V, 60W | AM20: 24 | AO20: Soldering Station | AP20: Đã kiểm kê 26/01/2026 | AS20: 19 | AU20: Đã nhận | AV20: 45964.379 | AW20: 46048.483 | AX20: - | AZ20: JIG | BD20: 46048.528 | BE20: NG | BF20: Jig_Equipment picture/PIE00019.jpg | BH20: Đúng | BL20: 137 | BN20: Đã nhận***26/01/2026 11:35:35 | BO20: ;Chưa trả***03/11/2025 09:05:11: __;Chưa trả***03/11/2025 09:05:11: 1660_Trịnh Trung Tuyến - PIE_Line 11;Đã nhận***26/01/2026 11:35:35 | BS20: Đã kiểm kê | BT20: 46048 | BU20: NG
A21: PIE00020 | B21: Soldering Station | C21: Máy hàn | D21: HAKO | E21: SLD 936 | H21: Common | J21: 220V, 60W | K21: No Need | N21: - | P21: No need | S21: - | T21: 1 | U21: Normal | V21: 50394 | X21: TS | AB21: EQ | AC21: PIE00020 | AF21: \\vnad\common\PIE\PIE STAFF 04 (Mr. Hoang)\2. Files, documents\File thiết bị\Hình ảnh\PIE00020.jpg | AG21: PIE00020 | AK21: PIE00020Soldering StationMáy hànHAKOSLD 936Common220V, 60W | AM21: 24 | AO21: Soldering Station | AP21: Đã kiểm kê 19/06/2026 | AS21: 20 | AU21: Đã nhận | AW21: 46192.746 | AX21: - | AZ21: JIG | BD21: 46192.751 | BE21: Bình thường | BF21: Jig_Equipment picture/PIE00020.jpg | BH21: Đúng | BK21: Tạm thời | BL21: 137 | BN21: Đã nhận***19/06/2026 17:54:41 | BO21: ;***;Đã nhận***19/06/2026 17:54:41 | BS21: Đã kiểm kê | BT21: 46192 | BU21: Trong thời hạn kiểm kê
A22: PIE00021 | B22: Soldering Station | C22: Máy hàn | D22: HAKO | E22: SLD 936 | H22: Common | J22: 220V, 60W | K22: No Need | N22: - | P22: No need | S22: - | T22: 1 | U22: Normal | V22: 50382 | X22: TS | AB22: EQ | AC22: PIE00021 | AF22: \\vnad\common\PIE\PIE STAFF 04 (Mr. Hoang)\2. Files, documents\File thiết bị\Hình ảnh\PIE00021.jpg | AG22: PIE00021 | AK22: PIE00021Soldering StationMáy hànHAKOSLD 936Common220V, 60W | AM22: 24 | AO22: Soldering Station | AP22: Đã kiểm kê 10/02/2026 | AS22: 21 | AU22: Đã nhận | AV22: 46024.41 | AW22: 46063.388 | AX22: - | AZ22: JIG | BD22: 46063.391 | BE22: Bình thường | BF22: Jig_Equipment picture/PIE00021.jpg | BH22: Đúng | BL22: 137 | BN22: Đã nhận***10/02/2026 09:18:53 | BO22: ;Chưa trả***02/01/2026 09:50:40: 537_Ngô Văn Phương - PIE_Line 4;Đã nhận***02/01/2026 15:14:37;Đã nhận***10/02/2026 09:18:53 | BS22: Đã kiểm kê | BT22: 46063 | BU22: Cần phải kiểm kê
A23: PIE00022 | B23: Soldering Station | C23: Máy hàn | D23: HAKO | E23: SLD 936 | H23: Common | J23: 220V, 60W | K23: No Need | N23: - | P23: No need | S23: - | T23: 1 | U23: Normal | V23: 50475 | X23: TS | AB23: EQ | AC23: PIE00022 | AF23: \\vnad\common\PIE\PIE STAFF 04 (Mr. Hoang)\2. Files, documents\File thiết bị\Hình ảnh\PIE00022.jpg | AG23: PIE00022 | AK23: PIE00022Soldering StationMáy hànHAKOSLD 936Common220V, 60W | AM23: 24 | AO23: Soldering Station | AP23: Đã kiểm kê 19/06/2026 | AS23: 22 | AU23: Đã nhận | AW23: 46192.747 | AX23: - | AZ23: JIG | BD23: 46192.751 | BE23: Bình thường | BF23: Jig_Equipment picture/PIE00022.jpg | BH23: Đúng | BK23: Tạm thời | BL23: 137 | BN23: Đã nhận***19/06/2026 17:55:24 | BO23: ;***;Đã nhận***19/06/2026 17:55:20;Đã nhận***19/06/2026 17:55:24 | BS23: Đã kiểm kê | BT23: 46192 | BU23: Trong thời hạn kiểm kê
A24: PIE00023 | B24: Hot Air Rework Station | C24: Trạm khò | D24: Quick | E24: QUICK 957DW+ | H24: Common | J24: 220V, 580W | K24: No Need | N24: - | P24: No need | S24: - | T24: 1 | U24: Normal | V24: 50880 | X24: TS | AB24: EQ | AC24: PIE00023 | AF24: \\vnad\common\PIE\PIE STAFF 04 (Mr. Hoang)\2. Files, documents\File thiết bị\Hình ảnh\PIE00023.jpg | AG24: PIE00023 | AK24: PIE00023Hot Air Rework StationTrạm khòQuickQUICK 957DW+Common220V, 580W | AM24: 24 | AO24: Hot Air Rework Station | AP24: Đã kiểm kê 12/12/2025 | AS24: 23 | AU24: Đã nhận | AW24: 45980.451 | AX24: - | AZ24: REPAIR | BD24: 46036.383 | BF24: Jig_Equipment picture/PIE00023.jpg | BH24: Đúng | BK24: Cố định | BL24: 9 | BN24: Đã nhận***19/11/2025 10:48:50 | BS24: Đã kiểm kê | BT24: 46003 | BU24: Cần phải kiểm kê
A25: PIE00024 | B25: Hot Air Rework Station | C25: Trạm khò | D25: Quick | E25: QUICK 957DW+ | H25: Common | J25: 220V, 580W | K25: No Need | N25: - | P25: No need | S25: - | T25: 1 | U25: Normal | V25: 50883 | X25: TS | AB25: EQ | AC25: PIE00024 | AF25: \\vnad\common\PIE\PIE STAFF 04 (Mr. Hoang)\2. Files, documents\File thiết bị\Hình ảnh\PIE00024.jpg | AG25: PIE00024 | AK25: PIE00024Hot Air Rework StationTrạm khòQuickQUICK 957DW+Common220V, 580W | AM25: 24 | AO25: Hot Air Rework Station | AP25: Đã kiểm kê 17/12/2025 | AS25: 24 | AZ25: REPAIR | BD25: 46036.383 | BF25: Jig_Equipment picture/PIE00024.jpg | BH25: Đúng | BK25: Cố định | BL25: 9 | BN25: *** | BO25: ;*** | BS25: Đã kiểm kê | BT25: 46008 | BU25: Cần phải kiểm kê
A26: PIE00025 | B26: Digital Oscilloscope | C26: Máy hiện sóng | D26: . | E26: TBS-1000C | F26: C013902 | H26: Roland | J26: 100-240V | K26: External | L26: 45994 | M26: 46359 | N26: Còn hiệu lực hiệu chuẩn | P26: No need | S26: - | T26: 1 | U26: Normal | V26: 50200 | X26: TS | AB26: EQ | AC26: PIE00025 | AF26: \\vnad\common\PIE\PIE STAFF 04 (Mr. Hoang)\2. Files, documents\File thiết bị\Hình ảnh\PIE00025.jpg | AG26: PIE00025 | AK26: PIE00025Digital OscilloscopeMáy hiện sóng.TBS-1000CC013902Roland100-240V | AM26: 24 | AO26: Digital Oscilloscope | AP26: Đã kiểm kê 18/12/2025 | AS26: 25 | AU26: Chưa trả | AV26: 45987.544 | AX26: 487 | AY26: Đỗ Ngọc Hải - PIE | AZ26: REPAIR | BA26: Mang đi hiệu chuẩn | BD26: 46036.383 | BE26: Empty | BF26: Jig_Equipment picture/PIE00025.jpg | BH26: Đúng | BK26: Cố định | BL26: 4 | BN26: Chưa trả***26/11/2025 13:03:18: 487_Đỗ Ngọc Hải - PIE_REPAIR | BO26: ;Chưa trả***26/11/2025 13:03:18: 487_Đỗ Ngọc Hải - PIE_REPAIR | BQ26: 01/06/2026 15:38:15 : External 12/03/2025 - 12/03/2026 _ TECHMASTER _ PASS | BR26: ;01/06/2026 15:37:25 : External 12/03/2025 - 08/13/2025 _ _;01/06/2026 15:37:44 : External 12/03/2025 - 12/03/2026 _ _;01/06/2026 15:38:02 : External 12/03/2025 - 12/03/2026 _ TECHMASTER _;01/06/2026 15:38:15 : External 12/03/2025 - 12/03/2026 _ TECHMASTER _ PASS | BS26: Đã kiểm kê | BT26: 46009 | BU26: Cần phải kiểm kê
A27: PIE00026 | B27: Screw driver | C27: Súng bắn vít | D27: Shuang Ai | E27: POL-SDGS-0530 | H27: Common | J27: 24VDC, 0,8 ~ 1,6 Nm | K27: No Need | N27: - | P27: No need | S27: - | T27: 1 | U27: Normal | X27: HTV | Y27: 45233 | Z27: VND 580,000 | AB27: EQ | AC27: PIE00026 | AF27: \\vnad\common\PIE\PIE STAFF 04 (Mr. Hoang)\2. Files, documents\File thiết bị\Hình ảnh\PIE00026.jpg | AG27: PIE00026 | AK27: PIE00026Screw driverSúng bắn vítShuang AiPOL-SDGS-0530Common24VDC, 0,8 ~ 1,6 Nm | AM27: 23 | AO27: Screw driver | AP27: Đã kiểm kê 06/11/2025 | AS27: 26 | AU27: Chưa trả | AV27: 45870.784 | AW27: 45870.784 | AX27: 813 | AY27: Phạm Đức Trung - PIE | AZ27: JIG | BA27: Súng xanh | BD27: 45967.591 | BE27: NG | BF27: Jig_Equipment picture/PIE00026.jpg | BH27: Đúng | BL27: 273 | BN27: Chưa trả***01/08/2025 18:49:03: 813_Phạm Đức Trung - PIE_JIG | BO27: ;Chưa trả***01/08/2025 18:49:03: 813_Phạm Đức Trung - PIE_JIG | BS27: Đã kiểm kê | BT27: 45967 | BU27: NG
A28: PIE00027 | B28: Screw driver | C28: Súng bắn vít | D28: Shuang Ai | E28: POL-SDGS-0530 | H28: Common | J28: 24VDC, 0,8 ~ 1,6 Nm | K28: No Need | N28: - | P28: No need | S28: - | T28: 1 | U28: Normal | X28: HTV | Y28: 45233 | Z28: VND 580,000 | AB28: EQ | AC28: PIE00027 | AF28: \\vnad\common\PIE\PIE STAFF 04 (Mr. Hoang)\2. Files, documents\File thiết bị\Hình ảnh\PIE00027.jpg | AG28: PIE00027 | AK28: PIE00027Screw driverSúng bắn vítShuang AiPOL-SDGS-0530Common24VDC, 0,8 ~ 1,6 Nm | AM28: 23 | AO28: Screw driver | AP28: Đã kiểm kê 07/04/2026 | AS28: 27 | AU28: Chưa trả | AV28: 46119.376 | AW28: 46034.66 | AX28: 837 | AY28: Chu Tiến Dũng - PIE | AZ28: Line 1 | BA28: Súng xanh | BD28: 46119.376 | BE28: NG | BF28: Jig_Equipment picture/PIE00027.jpg | BH28: Đúng | BL28: 273 | BN28: Chưa trả***07/04/2026 09:00:58: 837_Chu Tiến Dũng - PIE_Line 1 | BO28: ;***;Đã nhận***12/01/2026 15:50:12;Chưa trả***07/04/2026 09:00:58: 837_Chu Tiến Dũng - PIE_Line 1 | BS28: Đã kiểm kê | BT28: 46119 | BU28: NG
A29: PIE00028 | B29: Screw driver | C29: Súng bắn vít | D29: Shuang Ai | E29: POL-SDGS-0530 | H29: Common | J29: 24VDC, 0,8 ~ 1,6 Nm | K29: No Need | N29: - | P29: No need | S29: - | T29: 1 | U29: Normal | X29: HTV | Y29: 45233 | Z29: VND 580,000 | AB29: EQ | AC29: PIE00028 | AF29: \\vnad\common\PIE\PIE STAFF 04 (Mr. Hoang)\2. Files, documents\File thiết bị\Hình ảnh\PIE00028.jpg | AG29: PIE00028 | AK29: PIE00028Screw driverSúng bắn vítShuang AiPOL-SDGS-0530Common24VDC, 0,8 ~ 1,6 Nm | AM29: 23 | AO29: Screw driver | AP29: Đã kiểm kê 06/11/2025 | AS29: 28 | AZ29: JIG | BA29: Súng xanh | BD29: 45967.591 | BE29: NG | BF29: Jig_Equipment picture/PIE00028.jpg | BH29: Đúng | BL29: 273 | BN29: *** | BO29: ;*** | BS29: Đã kiểm kê | BT29: 45967 | BU29: NG
A30: PIE00029 | B30: Screw driver | C30: Súng bắn vít | D30: Shuang Ai | E30: POL-SDGS-0530 | H30: Common | J30: 24VDC, 0,8 ~ 1,6 Nm | K30: No Need | N30: - | P30: No need | S30: - | T30: 1 | U30: Normal | X30: HTV | Y30: 45233 | Z30: VND 580,000 | AB30: EQ | AC30: PIE00029 | AF30: \\vnad\common\PIE\PIE STAFF 04 (Mr. Hoang)\2. Files, documents\File thiết bị\Hình ảnh\PIE00029.jpg | AG30: PIE00029 | AK30: PIE00029Screw driverSúng bắn vítShuang AiPOL-SDGS-0530Common24VDC, 0,8 ~ 1,6 Nm | AM30: 23 | AO30: Screw driver | AP30: Đã kiểm kê 25/11/2025 | AS30: 29 | AU30: Chưa trả | AV30: 45986.402 | AX30: 1525 | AY30: Nguyễn Long Định - PIE | AZ30: Line 10 | BA30: Súng xanh | BD30: 45986.402 | BE30: NG | BF30: Jig_Equipment picture/PIE00029.jpg | BH30: Đúng | BL30: 273 | BN30: Chưa trả***25/11/2025 09:38:47: 1525_Nguyễn Long Định - PIE_Line 10 | BO30: ;*** | BS30: Đã kiểm kê | BT30: 45986 | BU30: NG
A31: PIE00030 | B31: Screw driver | C31: Súng bắn vít | D31: Shuang Ai | E31: POL-SDGS-0530 | H31: Common | J31: 24VDC, 0,8 ~ 1,6 Nm | K31: No Need | N31: - | P31: No need | S31: - | T31: 1 | U31: Normal | X31: HTV | Y31: 45233 | Z31: VND 580,000 | AB31: EQ | AC31: PIE00030 | AF31: \\vnad\common\PIE\PIE STAFF 04 (Mr. Hoang)\2. Files, documents\File thiết bị\Hình ảnh\PIE00030.jpg | AG31: PIE00030 | AK31: PIE00030Screw driverSúng bắn vítShuang AiPOL-SDGS-0530Common24VDC, 0,8 ~ 1,6 Nm | AM31: 23 | AO31: Screw driver | AP31: Đã kiểm kê 27/02/2026 | AS31: 30 | AU31: Đã nhận | AW31: 46080.571 | AX31: - | AZ31: JIG | BA31: Súng xanh | BD31: 46080.571 | BE31: NG | BF31: Jig_Equipment picture/PIE00030.jpg | BH31: Đúng | BL31: 273 | BN31: Đã nhận***27/02/2026 13:41:37 | BO31: ;***;Đã nhận***27/02/2026 13:41:37 | BS31: Đã kiểm kê | BT31: 46080 | BU31: NG
A32: PIE00031 | B32: Screw driver | C32: Súng bắn vít | E32: POL-SDGS-0530 | H32: Common | J32: 24VDC, 0,8 ~ 1,6 Nm | K32: No Need | N32: - | P32: No need | S32: - | T32: 1 | U32: Normal | X32: HTV | Y32: 45233 | Z32: VND 580,000 | AB32: EQ | AC32: PIE00031 | AF32: \\vnad\common\PIE\PIE STAFF 04 (Mr. Hoang)\2. Files, documents\File thiết bị\Hình ảnh\PIE00031.jpg | AG32: PIE00031 | AK32: PIE00031Screw driverSúng bắn vítPOL-SDGS-0530Common24VDC, 0,8 ~ 1,6 Nm | AM32: 23 | AO32: Screw driver | AP32: Đã kiểm kê 07/04/2026 | AS32: 31 | AU32: Chưa trả | AV32: 46119.376 | AW32: 46003.369 | AX32: 837 | AY32: Chu Tiến Dũng - PIE | AZ32: Line 1 | BA32: Súng xanh | BD32: 46119.376 | BE32: NG | BF32: Jig_Equipment picture/PIE00031.jpg | BH32: Đúng | BL32: 273 | BN32: Chưa trả***07/04/2026 09:01:30: 837_Chu Tiến Dũng - PIE_Line 1 | BO32: ;Chưa trả***07/04/2026 09:01:30: 837_Chu Tiến Dũng - PIE_Line 1 | BS32: Đã kiểm kê | BT32: 46119 | BU32: NG
A33: PIE00032 | B33: Screw driver | C33: Súng bắn vít | D33: Shuang Ai | E33: POL-SDGS-0115 | H33: Common | J33: 24VDC, 0,1 ~ 1 Nm | K33: No Need | N33: - | P33: No need | S33: - | T33: 1 | U33: Normal | X33: HTV | Y33: 45233 | Z33: VND 570,000 | AB33: EQ | AC33: PIE00032 | AF33: \\vnad\common\PIE\PIE STAFF 04 (Mr. Hoang)\2. Files, documents\File thiết bị\Hình ảnh\PIE00032.jpg | AG33: PIE00032 | AK33: PIE00032Screw driverSúng bắn vítShuang AiPOL-SDGS-0115Common24VDC, 0,1 ~ 1 Nm | AM33: 23 | AO33: Screw driver | AP33: Đã kiểm kê 15/12/2025 | AS33: 32 | AU33: Đã nhận | AW33: 46006.666 | AX33: - | AZ33: JIG | BA33: Súng bắn vít nhỏ | BD33: 46006.705 | BE33: NG | BF33: Jig_Equipment picture/PIE00032.jpg | BH33: Đúng | BL33: 273 | BN33: Đã nhận***15/12/2025 15:58:39 | BO33: ;Đã nhận***15/12/2025 15:58:39 | BS33: Đã kiểm kê | BT33: 46006 | BU33: NG
A34: PIE00033 | B34: Screw driver | C34: Súng bắn vít | D34: Shuang Ai | E34: POL-SDGS-0115 | H34: Common | J34: 24VDC, 0,1 ~ 1 Nm | K34: No Need | N34: - | P34: No need | S34: - | T34: 1 | U34: Normal | X34: HTV | Y34: 45233 | Z34: VND 570,000 | AB34: EQ | AC34: PIE00033 | AF34: \\vnad\common\PIE\PIE STAFF 04 (Mr. Hoang)\2. Files, documents\File thiết bị\Hình ảnh\PIE00033.jpg | AG34: PIE00033 | AK34: PIE00033Screw driverSúng bắn vítShuang AiPOL-SDGS-0115Common24VDC, 0,1 ~ 1 Nm | AM34: 23 | AO34: Screw driver | AP34: Đã kiểm kê 09/12/2025 | AS34: 33 | AZ34: REPAIR | BA34: Súng bắn vít nhỏ | BD34: 46036.383 | BE34: NG | BF34: Jig_Equipment picture/PIE00033.jpg | BH34: Đúng | BK34: Cố định | BL34: 273 | BN34: *** | BO34: ;*** | BS34: Đã kiểm kê | BT34: 46000 | BU34: NG
